Workbook

Sheet Classificados (v2)
A1: title | B1: authors | C1: year | D1: venue | E1: cluster | F1: paper_type | G1: citations | H1: doi | I1: Scopus (Percentil) | J1: SJR Quartile | K1: ISSN / e-ISSN | M1: ID | N1: Título | O1: Venue | P1: DOI | Q1: Qualis (2025-2028) | R1: Scopus (Percentil) | S1: SJR Quartile | T1: ISSN / e-ISSN | U1: Year | V1: Citações OpenAlex | W1: Citações Crossref | X1: Citações Scopus | Y1: Citações (verificado em) | Z1: ID
A2: Transforming cybersecurity with agentic AI to combat emerging cyber threats | B2: Nir Kshetri | C2: 2025 | D2: Telecommunications Policy | E2: Security IR / SOC | F2: unscreened(rule-classified) | G2: 51 | H2: 10.1016/j.telpol.2025.102976 | I2: =VLOOKUP($D2,Scopus!$A$2:$K$49,3,FALSE) -> 97.0% 14/541 Communication | J2: =VLOOKUP($D2,Scopus!$A$2:$K$49,10,FALSE) -> Q1 | K2: =VLOOKUP($D2,Scopus!$A$2:$K$49,11,FALSE) -> 0308-5961 | L2: =VLOOKUP(H2,$M$1:$Z$40,14,FALSE) -> #N/A | M2: P01 | N2: Trustworthy agentic AI systems: a cross-layer review of architectures, threat models and governance strategies | O2: F1000Research | P2: 10.12688/f1000research.169927.1 | Q2: A2 | R2: 0.77 | S2: Q1 | T2: 2046-1402 | U2: 2025 | V2: 19 | W2: 21 | X2: NÃO INDEXADO | Y2: 46230 | Z2: P01
A3: Deep Learning for Time Series Anomaly Detection: A Survey | B3: Zahra Zamanzadeh Darban; Geoffrey I. Webb; Shirui Pan; Charų C. Aggarwal; Mahsa Salehi | C3: 2024 | D3: ACM Computing Surveys | E3: Detection (classical ML) | F3: survey/position | G3: 506 | H3: 10.1145/3691338 | I3: =VLOOKUP($D3,Scopus!$A$2:$K$49,3,FALSE) -> 99.0% 1/241 General Computer Science | J3: =VLOOKUP($D3,Scopus!$A$2:$K$49,10,FALSE) -> Q1 | K3: =VLOOKUP($D3,Scopus!$A$2:$K$49,11,FALSE) -> 0360-0300 | L3: =VLOOKUP(H3,$M$1:$Z$40,14,FALSE) -> #N/A | M3: P02 | N3: The role of agentic AI in shaping a smart future: A systematic review | O3: Array | P3: 10.1016/j.array.2025.100399 | Q3: A1 | R3: 0.88 | S3: Q1 | T3: 2590-0056 | U3: 2025 | V3: 180 | W3: 190 | X3: 175 | Y3: 46230 | Z3: P02
A4: AgentAI: A comprehensive survey on autonomous agents in distributed AI for industry 4.0 | B4: Francesco Piccialli; Diletta Chiaro; Sundas Sarwar; Donato Cerciello; Pian Qi; Valeria Mele | C4: 2025 | D4: Expert Systems with Applications | E4: Agent foundations | F4: unscreened(rule-classified) | G4: 59 | H4: 10.1016/j.eswa.2025.128404 | I4: =VLOOKUP($D4,Scopus!$A$2:$K$49,3,FALSE) -> 97.0% 10/351 General Engineering | J4: =VLOOKUP($D4,Scopus!$A$2:$K$49,10,FALSE) -> Q1 | K4: =VLOOKUP($D4,Scopus!$A$2:$K$49,11,FALSE) -> 0957-4174 | L4: =VLOOKUP(H4,$M$1:$Z$40,14,FALSE) -> #N/A | M4: P03 | N4: A Research Landscape of Agentic AI and Large Language Models | O4: Algorithms | P4: 10.3390/a18080499 | Q4: A2 | R4: 0.78 | S4: Q2 | T4: 1999-4893 | U4: 2025 | V4: 38 | W4: 45 | X4: 39 | Y4: 46230 | Z4: P03
A5: LLM-Based Multi-Agent Systems for Software Engineering: Literature Review, Vision, and the Road Ahead | B5: Junda He; Christoph Treude; David Lo | C5: 2025 | D5: ACM Transactions on Software Engineering and Methodology | E5: Agent foundations | F5: unscreened(rule-classified) | G5: 177 | H5: 10.1145/3712003 | I5: =VLOOKUP($D5,Scopus!$A$2:$K$49,3,FALSE) -> 89.0% 53/503 Software | J5: =VLOOKUP($D5,Scopus!$A$2:$K$49,10,FALSE) -> Q1 | K5: =VLOOKUP($D5,Scopus!$A$2:$K$49,11,FALSE) -> 1049-331X | L5: =VLOOKUP(H5,$M$1:$Z$40,14,FALSE) -> #N/A | M5: P04 | N5: LLM-Based Multi-Agent Systems for Software Engineering | O5: ACM TRANSACTIONS ON SOFTWARE ENGINEERING AND METHODOLOGY | P5: 10.1145/3712003 | Q5: A2 | R5: 0.82 | S5: Q1 | T5: 1049-331X | U5: 2024 | V5: 144 | W5: 173 | X5: 134 | Y5: 46230 | Z5: P04
A6: AI Agents vs. Agentic AI: A Conceptual taxonomy, applications and challenges | B6: Ranjan Sapkota; Konstantinos I. Roumeliotis; Manoj Karkee | C6: 2025 | D6: Information Fusion | E6: Agent foundations | F6: survey/position | G6: 169 | H6: 10.1016/j.inffus.2025.103599 | I6: =VLOOKUP($D6,Scopus!$A$2:$K$49,3,FALSE) -> 99.0% 1/203 Signal Processing | J6: =VLOOKUP($D6,Scopus!$A$2:$K$49,10,FALSE) -> Q1 | K6: =VLOOKUP($D6,Scopus!$A$2:$K$49,11,FALSE) -> 1566-2535 | L6: =VLOOKUP(H6,$M$1:$Z$40,14,FALSE) -> #N/A | M6: P05 | N6: A Survey of AIOps in the Era of Large Language Models | O6: ACM Computing Surveys | P6: 10.1145/3746635 | Q6: A1 | R6: 0.99 | S6: Q1 | T6: 0360-0300 | U6: 2025 | V6: 19 | W6: 28 | X6: 24 | Y6: 46230 | Z6: P05
A7: Task Failure Prediction in Cloud Data Centers Using Deep Learning | B7: Jiechao Gao; Haoyu Wang; Haiying Shen | C7: 2020 | D7: IEEE Transactions on Services Computing | E7: Detection (classical ML) | F7: unscreened(rule-classified) | G7: 217 | H7: 10.1109/tsc.2020.2993728 | I7: =VLOOKUP($D7,Scopus!$A$2:$K$49,3,FALSE) -> 93.0% 17/245 Hardware and Architecture | J7: =VLOOKUP($D7,Scopus!$A$2:$K$49,10,FALSE) -> Q1 | K7: =VLOOKUP($D7,Scopus!$A$2:$K$49,11,FALSE) -> 1939-1374 | L7: =VLOOKUP(H7,$M$1:$Z$40,14,FALSE) -> #N/A | M7: P06 | N7: Agentic AI: A Comprehensive Survey of Technologies, Applications, and Societal Implications | O7: IEEE Access | P7: 10.1109/ACCESS.2025.3585609 | Q7: A1 | R7: 0.9 | S7: Q1 | T7: 2169-3536 | U7: 2025 | V7: 48 | W7: 57 | X7: 44 | Y7: 46230 | Z7: P06
A8: TAMO:Fine-Grained Root Cause Analysis via Tool-Assisted LLM Agent With Multi-Modality Observation Data in Cloud-Native Systems | B8: Xiao Zhang; Qi Wang; Mingyi Li; Yuan Yuan; Mengbai Xiao; Fuzhen Zhuang; Dongxiao Yu | C8: 2025 | D8: IEEE Transactions on Services Computing | E8: LLM / agentic ops | F8: unscreened(rule-classified) | G8: 7 | H8: 10.1109/TSC.2025.3629066 | I8: =VLOOKUP($D8,Scopus!$A$2:$K$49,3,FALSE) -> 93.0% 17/245 Hardware and Architecture | J8: =VLOOKUP($D8,Scopus!$A$2:$K$49,10,FALSE) -> Q1 | K8: =VLOOKUP($D8,Scopus!$A$2:$K$49,11,FALSE) -> 1939-1374 | L8: =VLOOKUP(H8,$M$1:$Z$40,14,FALSE) -> #N/A | M8: P07 | N8: Artificial Empathy: A New Perspective for Analyzing and Designing Multi-Agent Systems | O8: IEEE Access | P8: 10.1109/ACCESS.2020.3029502 | Q8: A1 | R8: 0.9 | S8: Q1 | T8: 2169-3536 | U8: 2020 | V8: 10 | W8: 9 | X8: 8 | Y8: 46230 | Z8: P07
A9: Surveying Root Cause Analysis Techniques: A Comprehensive Review of Aspects for Multi-Service Applications | B9: Zhijing Li; Jianbo Yu; Zhijun Huang; Yusheng Huang | C9: 2025 | D9: IEEE Transactions on Services Computing | E9: Root-cause analysis | F9: unscreened(rule-classified) | G9: 0 | H9: 10.1109/TSC.2025.3631913 | I9: =VLOOKUP($D9,Scopus!$A$2:$K$49,3,FALSE) -> 93.0% 17/245 Hardware and Architecture | J9: =VLOOKUP($D9,Scopus!$A$2:$K$49,10,FALSE) -> Q1 | K9: =VLOOKUP($D9,Scopus!$A$2:$K$49,11,FALSE) -> 1939-1374 | L9: =VLOOKUP(H9,$M$1:$Z$40,14,FALSE) -> #N/A | M9: P08 | N9: Applications, Challenges, and Future Directions of Human-in-the-Loop Learning | O9: IEEE Access | P9: 10.1109/ACCESS.2024.3401547 | Q9: A1 | R9: 0.9 | S9: Q1 | T9: 2169-3536 | U9: 2024 | V9: 135 | W9: 134 | X9: 141 | Y9: 46230 | Z9: P08
A10: A Research Landscape of Agentic AI and Large Language Models: Applications, Challenges and Future Directions | B10: Sarfraz Nawaz Brohi; Qurat-ul-ain Mastoi; N. Z. Jhanjhi; Thulasyammal Ramiah Pillai | C10: 2025 | D10: Algorithms | E10: Security IR / SOC | F10: unscreened(rule-classified) | G10: 44 | H10: 10.3390/a18080499 | I10: =VLOOKUP($D10,Scopus!$A$2:$K$49,3,FALSE) -> 84.0% 34/212 Computational Mathematics | J10: =VLOOKUP($D10,Scopus!$A$2:$K$49,10,FALSE) -> Q2 | K10: =VLOOKUP($D10,Scopus!$A$2:$K$49,11,FALSE) -> 1999-4893 | L10: =VLOOKUP(H10,$M$1:$Z$40,14,FALSE) -> #N/A | M10: P09 | N10: AI Agents vs. Agentic AI: A Conceptual taxonomy, applications and challenges | O10: Information Fusion | P10: 10.1016/j.inffus.2025.103599 | Q10: A1 | R10: 0.99 | S10: Q1 | T10: 1566-2535 | U10: 2025 | V10: 132 | W10: 149 | X10: 136 | Y10: 46230 | Z10: P09
A11: The Rise of Agentic AI: A Review of Definitions, Frameworks, Architectures, Applications, Evaluation Metrics, and Challenges | B11: Ajay Bandi; Bhavani Kongari; Roshini Naguru; Sahitya Pasnoor; Sri Vidya Vilipala | C11: 2025 | D11: Future Internet | E11: Security IR / SOC | F11: unscreened(rule-classified) | G11: 126 | H11: 10.3390/fi17090404 | I11: =VLOOKUP($D11,Scopus!$A$2:$K$49,3,FALSE) -> 88.0% 65/568 Computer Networks and Communications | J11: =VLOOKUP($D11,Scopus!$A$2:$K$49,10,FALSE) -> Q1 | K11: =VLOOKUP($D11,Scopus!$A$2:$K$49,11,FALSE) -> 1999-5903 | L11: =VLOOKUP(H11,$M$1:$Z$40,14,FALSE) -> #N/A | M11: P10 | N11: Agentic AI: Autonomous Intelligence for Complex Goals — A Comprehensive Survey | O11: IEEE Access | P11: 10.1109/ACCESS.2025.3532853 | Q11: A1 | R11: 0.9 | S11: Q1 | T11: 2169-3536 | U11: 2025 | V11: 487 | W11: 534 | X11: 509 | Y11: 46230 | Z11: P10
A12: Trustworthy agentic AI systems: a cross-layer review of architectures, threat models, and governance strategies for real-world deployment | B12: IBRAHIM ADABARA; Bashir Olaniyi Sadiq; Aliyu Nuhu Shuaibu; Yale Ibrahim Danjuma; Maninti Venkateswarlu | C12: 2025 | D12: F1000Research | E12: LLM / agentic ops | F12: unscreened(rule-classified) | G12: 21 | H12: 10.12688/f1000research.169927.1 | I12: =VLOOKUP($D12,Scopus!$A$2:$K$49,3,FALSE) -> 79.0% 139/692 Arts and Humanities (miscellaneous) | J12: =VLOOKUP($D12,Scopus!$A$2:$K$49,10,FALSE) -> Q1 | K12: =VLOOKUP($D12,Scopus!$A$2:$K$49,11,FALSE) -> 2046-1402 | L12: =VLOOKUP(H12,$M$1:$Z$40,14,FALSE) -> #N/A | M12: P11 | N12: Co-Evolving Multi-Agent Transfer Reinforcement Learning via Scenario Independent Representation | O12: IEEE Access | P12: 10.1109/ACCESS.2024.3430037 | Q12: A1 | R12: 0.9 | S12: Q1 | T12: 2169-3536 | U12: 2024 | V12: 9 | W12: 9 | X12: 10 | Y12: 46230 | Z12: P11
A13: A Review of Agentic AI in Cybersecurity: Cognitive Autonomy, Ethical Governance, and Quantum-Resilient Defense | B13: IBRAHIM ADABARA; Bashir Olaniyi Sadiq; Aliyu Nuhu Shuaibu; Yale Ibrahim Danjuma; Maninti Venkateswarlu | C13: 2025 | D13: F1000Research | E13: Security IR / SOC | F13: survey/position | G13: 13 | H13: 10.12688/f1000research.169337.1 | I13: =VLOOKUP($D13,Scopus!$A$2:$K$49,3,FALSE) -> 79.0% 139/692 Arts and Humanities (miscellaneous) | J13: =VLOOKUP($D13,Scopus!$A$2:$K$49,10,FALSE) -> Q1 | K13: =VLOOKUP($D13,Scopus!$A$2:$K$49,11,FALSE) -> 2046-1402 | L13: =VLOOKUP(H13,$M$1:$Z$40,14,FALSE) -> #N/A | M13: P12 | N13: Enhancing autonomous system security and resilience with generative AI | O13: IEEE Access | P13: 10.1109/ACCESS.2024.3439363 | Q13: A1 | R13: 0.9 | S13: Q1 | T13: 2169-3536 | U13: 2024 | V13: 86 | W13: 93 | X13: 101 | Y13: 46230 | Z13: P12
A14: A Practical Approach to Defining a Framework for Developing an Agentic AIOps System | B14: Răzvan Daniel Zota; Corneliu Bărbulescu; Radu Constantinescu | C14: 2025 | D14: Electronics | E14: LLM / agentic ops | F14: systems/empirical | G14: 24 | H14: 10.3390/electronics14091775 | I14: =VLOOKUP($D14,Scopus!$A$2:$K$49,3,FALSE) -> 83.0% 35/203 Signal Processing | J14: =VLOOKUP($D14,Scopus!$A$2:$K$49,10,FALSE) -> Q2 | K14: =VLOOKUP($D14,Scopus!$A$2:$K$49,11,FALSE) -> 2079-9292 | L14: =VLOOKUP(H14,$M$1:$Z$40,14,FALSE) -> #N/A | M14: P13 | N14: Retail Resilience Engine: An Agentic AI Framework for Building Reliable Retail Systems | O14: IEEE Access | P14: 10.1109/ACCESS.2025.3552592 | Q14: A1 | R14: 0.9 | S14: Q1 | T14: 2169-3536 | U14: 2025 | V14: 29 | W14: 33 | X14: 31 | Y14: 46230 | Z14: P13
... A40: Variational LSTM Enhanced Anomaly Detection for Industrial Big Data | B40: Xiaokang Zhou; Yiyong Hu; Wei Liang; Jianhua Ma; Qun Jin | C40: 2020 | D40: IEEE Transactions on Industrial Informatics | E40: Automated remediation | F40: unscreened(rule-classified) | G40: 401 | H40: 10.1109/tii.2020.3022432 | I40: =VLOOKUP($D40,Scopus!$A$2:$K$49,3,FALSE) -> 98.0% 10/519 Information Systems | J40: =VLOOKUP($D40,Scopus!$A$2:$K$49,10,FALSE) -> Q1 | K40: =VLOOKUP($D40,Scopus!$A$2:$K$49,11,FALSE) -> 1551-3203 | L40: =VLOOKUP(H40,$M$1:$Z$40,14,FALSE) -> #N/A | M40: P40 | N40: A Comprehensive Survey on LLM-Based Network Management and Operations | O40: International Journal of Network Management | P40: 10.1002/nem.70029 | Q40: A3 | R40: 0.68 | S40: Q2 | T40: 1055-7148 | U40: 2025 | V40: 11 | W40: 13 | X40: 7 | Y40: 46230 | Z40: P40
A41: Artificial Intelligence for Predictive Maintenance Applications: Key Components, Trustworthiness, and Future Trends | B41: Ayşegül Uçar; Mehmet Karaköse; Necim Kırımça | C41: 2024 | D41: Applied Sciences | E41: Detection (classical ML) | F41: survey/position | G41: 396 | H41: 10.3390/app14020898 | I41: =VLOOKUP($D41,Scopus!$A$2:$K$49,3,FALSE) -> 82.0% 18/99 Fluid Flow and Transfer Processes | J41: =VLOOKUP($D41,Scopus!$A$2:$K$49,10,FALSE) -> Q2 | K41: =VLOOKUP($D41,Scopus!$A$2:$K$49,11,FALSE) -> 2076-3417 | L41: =VLOOKUP(H41,$M$1:$Z$40,14,FALSE) -> #N/A
A42: Deep Industrial Image Anomaly Detection: A Survey | B42: Jiaqi Liu; Guoyang Xie; Jinbao Wang; Shangnian Li; Chengjie Wang; Feng Zheng; Yaochu Jin | C42: 2024 | D42: Machine Intelligence Research | E42: Detection (classical ML) | F42: survey/position | G42: 389 | H42: 10.1007/s11633-023-1459-z | I42: =VLOOKUP($D42,Scopus!$A$2:$K$49,3,FALSE) -> 99.0% 2/397 Modeling and Simulation | J42: =VLOOKUP($D42,Scopus!$A$2:$K$49,10,FALSE) -> Q1 | K42: =VLOOKUP($D42,Scopus!$A$2:$K$49,11,FALSE) -> 2731-538X | L42: =VLOOKUP(H42,$M$1:$Z$40,14,FALSE) -> #N/A
A43: Anomaly detection with density estimation | B43: Benjamin Nachman; David Shih | C43: 2020 | D43: Physical review D | E43: Detection (classical ML) | F43: systems/empirical | G43: 315 | H43: 10.1103/physrevd.101.075042 | I43: =VLOOKUP($D43,Scopus!$A$2:$K$49,3,FALSE) -> 93.0% 7/97 Nuclear and High Energy Physics | J43: =VLOOKUP($D43,Scopus!$A$2:$K$49,10,FALSE) -> Q1 | K43: =VLOOKUP($D43,Scopus!$A$2:$K$49,11,FALSE) -> 2470-0010 | L43: =VLOOKUP(H43,$M$1:$Z$40,14,FALSE) -> #N/A
A44: From Corrective to Predictive Maintenance—A Review of Maintenance Approaches for the Power Industry | B44: Marek Molęda; Bożena Małysiak-Mrozek; Weiping Ding; Vaidy Sunderam; Dariusz Mrozek | C44: 2023 | D44: Sensors | E44: Detection (classical ML) | F44: survey/position | G44: 264 | H44: 10.3390/s23135970 | I44: =VLOOKUP($D44,Scopus!$A$2:$K$49,3,FALSE) -> 91.0% 19/206 Instrumentation | J44: =VLOOKUP($D44,Scopus!$A$2:$K$49,10,FALSE) -> Q1 | K44: =VLOOKUP($D44,Scopus!$A$2:$K$49,11,FALSE) -> 1424-8220 | L44: =VLOOKUP(H44,$M$1:$Z$40,14,FALSE) -> #N/A
A45: From knowledge-based to big data analytic model: a novel IoT and machine learning based decision support system for predictive maintenance in Industry 4.0 | B45: Riccardo Rosati; Luca Romeo; Gianalberto Cecchini; F. Tonetto; Paolo Viti; Adriano Mancini; Emanuele Frontoni | C45: 2022 | D45: Journal of Intelligent Manufacturing | E45: Detection (classical ML) | F45: systems/empirical | G45: 247 | H45: 10.1007/s10845-022-01960-x | I45: =VLOOKUP($D45,Scopus!$A$2:$K$49,3,FALSE) -> 96.0% 17/503 Software | J45: =VLOOKUP($D45,Scopus!$A$2:$K$49,10,FALSE) -> Q1 | K45: =VLOOKUP($D45,Scopus!$A$2:$K$49,11,FALSE) -> 0956-5515 | L45: =VLOOKUP(H45,$M$1:$Z$40,14,FALSE) -> #N/A
A46: A Neuroergonomics Approach to Mental Workload, Engagement and Human Performance | B46: Frédéric Dehais; Alex Lafont; Raphaëlle N. Roy; Stephen Fairclough | C46: 2020 | D46: Frontiers in Neuroscience | E46: Human factors | F46: survey/position | G46: 245 | H46: 10.3389/fnins.2020.00268 | I46: =VLOOKUP($D46,Scopus!$A$2:$K$49,3,FALSE) -> 74.0% 29/112 General Neuroscience | J46: =VLOOKUP($D46,Scopus!$A$2:$K$49,10,FALSE) -> Q2 | K46: =VLOOKUP($D46,Scopus!$A$2:$K$49,11,FALSE) -> 1662-453X | L46: =VLOOKUP(H46,$M$1:$Z$40,14,FALSE) -> #N/A
A47: The Chatbot Usability Scale: the Design and Pilot of a Usability Scale for Interaction with AI-Based Conversational Agents | B47: Simone Borsci; Alessio Malizia; Martin Schmettow; Frank van der Velde; Gunay Tariverdiyeva; Divyaa Balaji; Alan Chamberlain | C47: 2021 | D47: Personal and Ubiquitous Computing | E47: Benchmarks & evaluation | F47: unscreened(rule-classified) | G47: 233 | H47: 10.1007/s00779-021-01582-9 | I47: =VLOOKUP($D47,Scopus!$A$2:$K$49,3,FALSE) -> 92.0% 24/296 Library and Information Sciences | J47: =VLOOKUP($D47,Scopus!$A$2:$K$49,10,FALSE) -> Q2 | K47: =VLOOKUP($D47,Scopus!$A$2:$K$49,11,FALSE) -> 1617-4909 | L47: =VLOOKUP(H47,$M$1:$Z$40,14,FALSE) -> #N/A
A48: A Review of Machine Learning and Deep Learning Techniques for Anomaly Detection in IoT Data | B48: Redhwan Al-amri; Raja Kumar Murugesan; Mustafa Man; Alaa Fareed; Mohammed A. Al‐Sharafi; Ammar Ahmed Alkahtani | C48: 2021 | D48: Applied Sciences | E48: Detection (classical ML) | F48: survey/position | G48: 202 | H48: 10.3390/app11125320 | I48: =VLOOKUP($D48,Scopus!$A$2:$K$49,3,FALSE) -> 82.0% 18/99 Fluid Flow and Transfer Processes | J48: =VLOOKUP($D48,Scopus!$A$2:$K$49,10,FALSE) -> Q2 | K48: =VLOOKUP($D48,Scopus!$A$2:$K$49,11,FALSE) -> 2076-3417 | L48: =VLOOKUP(H48,$M$1:$Z$40,14,FALSE) -> #N/A
A49: Deep learning for anomaly detection in log data: A survey | B49: Max Landauer; Sebastian Onder; Florian Skopik; Markus Wurzenberger | C49: 2023 | D49: Machine Learning with Applications | E49: Detection (classical ML) | F49: survey/position | G49: 194 | H49: 10.1016/j.mlwa.2023.100470 | I49: =VLOOKUP($D49,Scopus!$A$2:$K$49,3,FALSE) -> 93.0% 13/203 Computational Theory and Mathematics | J49: =VLOOKUP($D49,Scopus!$A$2:$K$49,10,FALSE) -> Q1 | K49: =VLOOKUP($D49,Scopus!$A$2:$K$49,11,FALSE) -> 2666-8270 | L49: =VLOOKUP(H49,$M$1:$Z$40,14,FALSE) -> #N/A
A50: Zero Touch Management: A Survey of Network Automation Solutions for 5G and 6G Networks | B50: Estefanía Coronado; Rasoul Behravesh; Tejas Subramanya; Adriana Fernández–Fernández; Muhammad Shuaib Siddiqui; Xavier Costa‐Pérez; Roberto Riggio | C50: 2022 | D50: IEEE Communications Surveys and Tutorials | E50: Security IR / SOC | F50: unscreened(rule-classified) | G50: 176 | H50: 10.1109/comst.2022.3212586 | I50: =VLOOKUP($D50,Scopus!$A$2:$K$49,3,FALSE) -> 99.0% 1/1030 Electrical and Electronic Engineering | J50: =VLOOKUP($D50,Scopus!$A$2:$K$49,10,FALSE) -> Q1 | K50: =VLOOKUP($D50,Scopus!$A$2:$K$49,11,FALSE) -> 1553-877X | L50: =VLOOKUP(H50,$M$1:$Z$40,14,FALSE) -> #N/A
A51: EADN: An Efficient Deep Learning Model for Anomaly Detection in Videos | B51: Sareer Ul Amin; Mohib Ullah; Muhammad Sajjad; Faouzi Alaya Cheikh; Mohammad Hijji; Abdulrahman Hijji; Khan Muhammad | C51: 2022 | D51: Mathematics | E51: Detection (classical ML) | F51: systems/empirical | G51: 142 | H51: 10.3390/math10091555 | I51: =VLOOKUP($D51,Scopus!$A$2:$K$49,3,FALSE) -> 92.0% 33/414 General Mathematics | J51: =VLOOKUP($D51,Scopus!$A$2:$K$49,10,FALSE) -> Q2 | K51: =VLOOKUP($D51,Scopus!$A$2:$K$49,11,FALSE) -> 2227-7390 | L51: =VLOOKUP(H51,$M$1:$Z$40,14,FALSE) -> #N/A
A52: Towards Synoptic Water Monitoring Systems: A Review of AI Methods for Automating Water Body Detection and Water Quality Monitoring Using Remote Sensing | B52: Liping Yang; Joshua Driscol; Sarigai Sarigai; Qiusheng Wu; Christopher D. Lippitt; Melinda Morgan | C52: 2022 | D52: Sensors | E52: Detection (classical ML) | F52: unscreened(rule-classified) | G52: 124 | H52: 10.3390/s22062416 | I52: =VLOOKUP($D52,Scopus!$A$2:$K$49,3,FALSE) -> 91.0% 19/206 Instrumentation | J52: =VLOOKUP($D52,Scopus!$A$2:$K$49,10,FALSE) -> Q1 | K52: =VLOOKUP($D52,Scopus!$A$2:$K$49,11,FALSE) -> 1424-8220 | L52: =VLOOKUP(H52,$M$1:$Z$40,14,FALSE) -> #N/A
... A89: An LLM-Based Agentic Network Traffic Incident-Report Approach Towards Explainable-AI Network Defense | B89: Chia-Hong Chou; Arjun Sudheer; Younghee Park | C89: 2026 | D89: Journal of Sensor and Actuator Networks | E89: LLM / agentic ops | F89: systems/empirical | G89: 1 | H89: 10.3390/jsan15020032 | I89: =VLOOKUP($D89,Scopus!$A$2:$K$49,3,FALSE) -> 97.0% 6/198 Control and Optimization | J89: =VLOOKUP($D89,Scopus!$A$2:$K$49,10,FALSE) -> Q2 | K89: =VLOOKUP($D89,Scopus!$A$2:$K$49,11,FALSE) -> 2224-2708 | L89: =VLOOKUP(H89,$M$1:$Z$40,14,FALSE) -> #N/A
A90: VAGNet: Vision-based Accident Anticipation with Global Features | B90: Vipooshan Vipulananthan; Charith D. Chitraranjan | C90: 2026 | D90: IEEE Open Journal of Vehicular Technology, vol. 7, pp. 1873-1883, 2026 | E90: Alert triage & correlation | F90: unscreened(rule-classified) | H90: 10.1109/ojvt.2026.3704953 | I90: =VLOOKUP($D90,Scopus!$A$2:$K$49,3,FALSE) -> #N/A | J90: =VLOOKUP($D90,Scopus!$A$2:$K$49,10,FALSE) -> #N/A | K90: =VLOOKUP($D90,Scopus!$A$2:$K$49,11,FALSE) -> #N/A | L90: =VLOOKUP(H90,$M$1:$Z$40,14,FALSE) -> #N/A
A91: TELESTO: A Graph Neural Network Model for Anomaly Classification in Cloud Services | B91: Dominik Scheinert; Alexander Acker | C91: 2021 | D91: Springer ICSOC LNCS 12632 (2020) 214-227 | E91: Automated remediation | F91: unscreened(rule-classified) | H91: 10.1007/978-3-030-76352-7_23 | I91: =VLOOKUP($D91,Scopus!$A$2:$K$49,3,FALSE) -> #N/A | J91: =VLOOKUP($D91,Scopus!$A$2:$K$49,10,FALSE) -> #N/A | K91: =VLOOKUP($D91,Scopus!$A$2:$K$49,11,FALSE) -> #N/A | L91: =VLOOKUP(H91,$M$1:$Z$40,14,FALSE) -> #N/A
A92: A Decentralised Self-Healing Approach for Network Topology Maintenance | B92: Arles Rodríguez; Jonatan Gómez; Ada Diaconescu | C92: 2020 | D92: Autonomous Agents and Multi-Agent Systems | E92: Automated remediation | F92: systems/empirical | H92: 10.1007/s10458-020-09486-3 | I92: =VLOOKUP($D92,Scopus!$A$2:$K$49,3,FALSE) -> 76.0% 137/570 Artificial Intelligence | J92: =VLOOKUP($D92,Scopus!$A$2:$K$49,10,FALSE) -> Q2 | K92: =VLOOKUP($D92,Scopus!$A$2:$K$49,11,FALSE) -> 1387-2532 | L92: =VLOOKUP(H92,$M$1:$Z$40,14,FALSE) -> #N/A
A93: A unified framework for detecting point and collective anomalies in operating system logs via collaborative transformers | B93: Mohammad Nasirzadeh; Jafar Tahmoresnezhad; Parviz Rashidi-Khazaee | C93: 2025 | D93: Scientific Reports | E93: Detection (classical ML) | F93: systems/empirical | H93: 10.1038/s41598-025-27693-4 | I93: =VLOOKUP($D93,Scopus!$A$2:$K$49,3,FALSE) -> 87.0% 29/223 | J93: =VLOOKUP($D93,Scopus!$A$2:$K$49,10,FALSE) -> Q1 | K93: =VLOOKUP($D93,Scopus!$A$2:$K$49,11,FALSE) -> 2045-2322 | L93: =VLOOKUP(H93,$M$1:$Z$40,14,FALSE) -> #N/A
A94: TARGET: Automated Scenario Generation from Traffic Rules for Testing Autonomous Vehicles via Validated LLM-Guided Knowledge Extraction | B94: Yao Deng; Jiaohong Yao; Zhi Tu; Xi Zheng; Mengshi Zhang; Tianyi Zhang | C94: 2023 | D94: IEEE Transactions on Software Engineering | E94: LLM / agentic ops | F94: unscreened(rule-classified) | H94: 10.1109/tse.2025.3569086 | I94: =VLOOKUP($D94,Scopus!$A$2:$K$49,3,FALSE) -> 92.0% 36/503 Software | J94: =VLOOKUP($D94,Scopus!$A$2:$K$49,10,FALSE) -> Q1 | K94: =VLOOKUP($D94,Scopus!$A$2:$K$49,11,FALSE) -> 0098-5589 | L94: =VLOOKUP(H94,$M$1:$Z$40,14,FALSE) -> #N/A

Sheet Classificados
A1: title | B1: authors | C1: year | D1: venue | E1: cluster | F1: paper_type | G1: citations | H1: doi | I1: Scopus (Percentil) | J1: SJR Quartile | K1: ISSN / e-ISSN | M1: ID | N1: Título | O1: Venue | P1: DOI | Q1: Qualis (2025-2028) | R1: Scopus (Percentil) | S1: SJR Quartile | T1: ISSN / e-ISSN | U1: Year | V1: Citações OpenAlex | W1: Citações Crossref | X1: Citações Scopus | Y1: Citações (verificado em) | Z1: ID
A2: Transforming cybersecurity with agentic AI to combat emerging cyber threats | B2: Nir Kshetri | C2: 2025 | D2: Telecommunications Policy | E2: Security IR / SOC | F2: unscreened(rule-classified) | G2: 51 | H2: 10.1016/j.telpol.2025.102976 | I2: =VLOOKUP($D2,Scopus!$A$2:$K$49,3,FALSE) -> 97.0% 14/541 Communication | J2: =VLOOKUP($D2,Scopus!$A$2:$K$49,10,FALSE) -> Q1 | K2: =VLOOKUP($D2,Scopus!$A$2:$K$49,11,FALSE) -> 0308-5961 | L2: =VLOOKUP(H2,$M$1:$Z$40,14,FALSE) -> #N/A | M2: P01 | N2: Trustworthy agentic AI systems: a cross-layer review of architectures, threat models and governance strategies | O2: F1000Research | P2: 10.12688/f1000research.169927.1 | Q2: A2 | R2: 0.77 | S2: Q1 | T2: 2046-1402 | U2: 2025 | V2: 19 | W2: 21 | X2: NÃO INDEXADO | Y2: 46230 | Z2: P01
A3: Deep Learning for Time Series Anomaly Detection: A Survey | B3: Zahra Zamanzadeh Darban; Geoffrey I. Webb; Shirui Pan; Charų C. Aggarwal; Mahsa Salehi | C3: 2024 | D3: ACM Computing Surveys | E3: Detection (classical ML) | F3: survey/position | G3: 506 | H3: 10.1145/3691338 | I3: =VLOOKUP($D3,Scopus!$A$2:$K$49,3,FALSE) -> 99.0% 1/241 General Computer Science | J3: =VLOOKUP($D3,Scopus!$A$2:$K$49,10,FALSE) -> Q1 | K3: =VLOOKUP($D3,Scopus!$A$2:$K$49,11,FALSE) -> 0360-0300 | L3: =VLOOKUP(H3,$M$1:$Z$40,14,FALSE) -> #N/A | M3: P02 | N3: The role of agentic AI in shaping a smart future: A systematic review | O3: Array | P3: 10.1016/j.array.2025.100399 | Q3: A1 | R3: 0.88 | S3: Q1 | T3: 2590-0056 | U3: 2025 | V3: 180 | W3: 190 | X3: 175 | Y3: 46230 | Z3: P02
A4: AgentAI: A comprehensive survey on autonomous agents in distributed AI for industry 4.0 | B4: Francesco Piccialli; Diletta Chiaro; Sundas Sarwar; Donato Cerciello; Pian Qi; Valeria Mele | C4: 2025 | D4: Expert Systems with Applications | E4: Agent foundations | F4: unscreened(rule-classified) | G4: 59 | H4: 10.1016/j.eswa.2025.128404 | I4: =VLOOKUP($D4,Scopus!$A$2:$K$49,3,FALSE) -> 97.0% 10/351 General Engineering | J4: =VLOOKUP($D4,Scopus!$A$2:$K$49,10,FALSE) -> Q1 | K4: =VLOOKUP($D4,Scopus!$A$2:$K$49,11,FALSE) -> 0957-4174 | L4: =VLOOKUP(H4,$M$1:$Z$40,14,FALSE) -> #N/A | M4: P03 | N4: A Research Landscape of Agentic AI and Large Language Models | O4: Algorithms | P4: 10.3390/a18080499 | Q4: A2 | R4: 0.78 | S4: Q2 | T4: 1999-4893 | U4: 2025 | V4: 38 | W4: 45 | X4: 39 | Y4: 46230 | Z4: P03
A5: LLM-Based Multi-Agent Systems for Software Engineering: Literature Review, Vision, and the Road Ahead | B5: Junda He; Christoph Treude; David Lo | C5: 2025 | D5: ACM Transactions on Software Engineering and Methodology | E5: Agent foundations | F5: unscreened(rule-classified) | G5: 177 | H5: 10.1145/3712003 | I5: =VLOOKUP($D5,Scopus!$A$2:$K$49,3,FALSE) -> 89.0% 53/503 Software | J5: =VLOOKUP($D5,Scopus!$A$2:$K$49,10,FALSE) -> Q1 | K5: =VLOOKUP($D5,Scopus!$A$2:$K$49,11,FALSE) -> 1049-331X | L5: =VLOOKUP(H5,$M$1:$Z$40,14,FALSE) -> #N/A | M5: P04 | N5: LLM-Based Multi-Agent Systems for Software Engineering | O5: ACM TRANSACTIONS ON SOFTWARE ENGINEERING AND METHODOLOGY | P5: 10.1145/3712003 | Q5: A2 | R5: 0.82 | S5: Q1 | T5: 1049-331X | U5: 2024 | V5: 144 | W5: 173 | X5: 134 | Y5: 46230 | Z5: P04
A6: AI Agents vs. Agentic AI: A Conceptual taxonomy, applications and challenges | B6: Ranjan Sapkota; Konstantinos I. Roumeliotis; Manoj Karkee | C6: 2025 | D6: Information Fusion | E6: Agent foundations | F6: survey/position | G6: 169 | H6: 10.1016/j.inffus.2025.103599 | I6: =VLOOKUP($D6,Scopus!$A$2:$K$49,3,FALSE) -> 99.0% 1/203 Signal Processing | J6: =VLOOKUP($D6,Scopus!$A$2:$K$49,10,FALSE) -> Q1 | K6: =VLOOKUP($D6,Scopus!$A$2:$K$49,11,FALSE) -> 1566-2535 | L6: =VLOOKUP(H6,$M$1:$Z$40,14,FALSE) -> #N/A | M6: P05 | N6: A Survey of AIOps in the Era of Large Language Models | O6: ACM Computing Surveys | P6: 10.1145/3746635 | Q6: A1 | R6: 0.99 | S6: Q1 | T6: 0360-0300 | U6: 2025 | V6: 19 | W6: 28 | X6: 24 | Y6: 46230 | Z6: P05
A7: Task Failure Prediction in Cloud Data Centers Using Deep Learning | B7: Jiechao Gao; Haoyu Wang; Haiying Shen | C7: 2020 | D7: IEEE Transactions on Services Computing | E7: Detection (classical ML) | F7: unscreened(rule-classified) | G7: 217 | H7: 10.1109/tsc.2020.2993728 | I7: =VLOOKUP($D7,Scopus!$A$2:$K$49,3,FALSE) -> 93.0% 17/245 Hardware and Architecture | J7: =VLOOKUP($D7,Scopus!$A$2:$K$49,10,FALSE) -> Q1 | K7: =VLOOKUP($D7,Scopus!$A$2:$K$49,11,FALSE) -> 1939-1374 | L7: =VLOOKUP(H7,$M$1:$Z$40,14,FALSE) -> #N/A | M7: P06 | N7: Agentic AI: A Comprehensive Survey of Technologies, Applications, and Societal Implications | O7: IEEE Access | P7: 10.1109/ACCESS.2025.3585609 | Q7: A1 | R7: 0.9 | S7: Q1 | T7: 2169-3536 | U7: 2025 | V7: 48 | W7: 57 | X7: 44 | Y7: 46230 | Z7: P06
A8: TAMO:Fine-Grained Root Cause Analysis via Tool-Assisted LLM Agent With Multi-Modality Observation Data in Cloud-Native Systems | B8: Xiao Zhang; Qi Wang; Mingyi Li; Yuan Yuan; Mengbai Xiao; Fuzhen Zhuang; Dongxiao Yu | C8: 2025 | D8: IEEE Transactions on Services Computing | E8: LLM / agentic ops | F8: unscreened(rule-classified) | G8: 7 | H8: 10.1109/TSC.2025.3629066 | I8: =VLOOKUP($D8,Scopus!$A$2:$K$49,3,FALSE) -> 93.0% 17/245 Hardware and Architecture | J8: =VLOOKUP($D8,Scopus!$A$2:$K$49,10,FALSE) -> Q1 | K8: =VLOOKUP($D8,Scopus!$A$2:$K$49,11,FALSE) -> 1939-1374 | L8: =VLOOKUP(H8,$M$1:$Z$40,14,FALSE) -> #N/A | M8: P07 | N8: Artificial Empathy: A New Perspective for Analyzing and Designing Multi-Agent Systems | O8: IEEE Access | P8: 10.1109/ACCESS.2020.3029502 | Q8: A1 | R8: 0.9 | S8: Q1 | T8: 2169-3536 | U8: 2020 | V8: 10 | W8: 9 | X8: 8 | Y8: 46230 | Z8: P07
A9: Surveying Root Cause Analysis Techniques: A Comprehensive Review of Aspects for Multi-Service Applications | B9: Zhijing Li; Jianbo Yu; Zhijun Huang; Yusheng Huang | C9: 2025 | D9: IEEE Transactions on Services Computing | E9: Root-cause analysis | F9: unscreened(rule-classified) | G9: 0 | H9: 10.1109/TSC.2025.3631913 | I9: =VLOOKUP($D9,Scopus!$A$2:$K$49,3,FALSE) -> 93.0% 17/245 Hardware and Architecture | J9: =VLOOKUP($D9,Scopus!$A$2:$K$49,10,FALSE) -> Q1 | K9: =VLOOKUP($D9,Scopus!$A$2:$K$49,11,FALSE) -> 1939-1374 | L9: =VLOOKUP(H9,$M$1:$Z$40,14,FALSE) -> #N/A | M9: P08 | N9: Applications, Challenges, and Future Directions of Human-in-the-Loop Learning | O9: IEEE Access | P9: 10.1109/ACCESS.2024.3401547 | Q9: A1 | R9: 0.9 | S9: Q1 | T9: 2169-3536 | U9: 2024 | V9: 135 | W9: 134 | X9: 141 | Y9: 46230 | Z9: P08
A10: A Research Landscape of Agentic AI and Large Language Models: Applications, Challenges and Future Directions | B10: Sarfraz Nawaz Brohi; Qurat-ul-ain Mastoi; N. Z. Jhanjhi; Thulasyammal Ramiah Pillai | C10: 2025 | D10: Algorithms | E10: Security IR / SOC | F10: unscreened(rule-classified) | G10: 44 | H10: 10.3390/a18080499 | I10: =VLOOKUP($D10,Scopus!$A$2:$K$49,3,FALSE) -> 84.0% 34/212 Computational Mathematics | J10: =VLOOKUP($D10,Scopus!$A$2:$K$49,10,FALSE) -> Q2 | K10: =VLOOKUP($D10,Scopus!$A$2:$K$49,11,FALSE) -> 1999-4893 | L10: =VLOOKUP(H10,$M$1:$Z$40,14,FALSE) -> #N/A | M10: P09 | N10: AI Agents vs. Agentic AI: A Conceptual taxonomy, applications and challenges | O10: Information Fusion | P10: 10.1016/j.inffus.2025.103599 | Q10: A1 | R10: 0.99 | S10: Q1 | T10: 1566-2535 | U10: 2025 | V10: 132 | W10: 149 | X10: 136 | Y10: 46230 | Z10: P09
A11: The Rise of Agentic AI: A Review of Definitions, Frameworks, Architectures, Applications, Evaluation Metrics, and Challenges | B11: Ajay Bandi; Bhavani Kongari; Roshini Naguru; Sahitya Pasnoor; Sri Vidya Vilipala | C11: 2025 | D11: Future Internet | E11: Security IR / SOC | F11: unscreened(rule-classified) | G11: 126 | H11: 10.3390/fi17090404 | I11: =VLOOKUP($D11,Scopus!$A$2:$K$49,3,FALSE) -> 88.0% 65/568 Computer Networks and Communications | J11: =VLOOKUP($D11,Scopus!$A$2:$K$49,10,FALSE) -> Q1 | K11: =VLOOKUP($D11,Scopus!$A$2:$K$49,11,FALSE) -> 1999-5903 | L11: =VLOOKUP(H11,$M$1:$Z$40,14,FALSE) -> #N/A | M11: P10 | N11: Agentic AI: Autonomous Intelligence for Complex Goals — A Comprehensive Survey | O11: IEEE Access | P11: 10.1109/ACCESS.2025.3532853 | Q11: A1 | R11: 0.9 | S11: Q1 | T11: 2169-3536 | U11: 2025 | V11: 487 | W11: 534 | X11: 509 | Y11: 46230 | Z11: P10
A12: Trustworthy agentic AI systems: a cross-layer review of architectures, threat models, and governance strategies for real-world deployment | B12: IBRAHIM ADABARA; Bashir Olaniyi Sadiq; Aliyu Nuhu Shuaibu; Yale Ibrahim Danjuma; Maninti Venkateswarlu | C12: 2025 | D12: F1000Research | E12: LLM / agentic ops | F12: unscreened(rule-classified) | G12: 21 | H12: 10.12688/f1000research.169927.1 | I12: =VLOOKUP($D12,Scopus!$A$2:$K$49,3,FALSE) -> 79.0% 139/692 Arts and Humanities (miscellaneous) | J12: =VLOOKUP($D12,Scopus!$A$2:$K$49,10,FALSE) -> Q1 | K12: =VLOOKUP($D12,Scopus!$A$2:$K$49,11,FALSE) -> 2046-1402 | L12: =VLOOKUP(H12,$M$1:$Z$40,14,FALSE) -> #N/A | M12: P11 | N12: Co-Evolving Multi-Agent Transfer Reinforcement Learning via Scenario Independent Representation | O12: IEEE Access | P12: 10.1109/ACCESS.2024.3430037 | Q12: A1 | R12: 0.9 | S12: Q1 | T12: 2169-3536 | U12: 2024 | V12: 9 | W12: 9 | X12: 10 | Y12: 46230 | Z12: P11
A13: A Review of Agentic AI in Cybersecurity: Cognitive Autonomy, Ethical Governance, and Quantum-Resilient Defense | B13: IBRAHIM ADABARA; Bashir Olaniyi Sadiq; Aliyu Nuhu Shuaibu; Yale Ibrahim Danjuma; Maninti Venkateswarlu | C13: 2025 | D13: F1000Research | E13: Security IR / SOC | F13: survey/position | G13: 13 | H13: 10.12688/f1000research.169337.1 | I13: =VLOOKUP($D13,Scopus!$A$2:$K$49,3,FALSE) -> 79.0% 139/692 Arts and Humanities (miscellaneous) | J13: =VLOOKUP($D13,Scopus!$A$2:$K$49,10,FALSE) -> Q1 | K13: =VLOOKUP($D13,Scopus!$A$2:$K$49,11,FALSE) -> 2046-1402 | L13: =VLOOKUP(H13,$M$1:$Z$40,14,FALSE) -> #N/A | M13: P12 | N13: Enhancing autonomous system security and resilience with generative AI | O13: IEEE Access | P13: 10.1109/ACCESS.2024.3439363 | Q13: A1 | R13: 0.9 | S13: Q1 | T13: 2169-3536 | U13: 2024 | V13: 86 | W13: 93 | X13: 101 | Y13: 46230 | Z13: P12
A14: A Practical Approach to Defining a Framework for Developing an Agentic AIOps System | B14: Răzvan Daniel Zota; Corneliu Bărbulescu; Radu Constantinescu | C14: 2025 | D14: Electronics | E14: LLM / agentic ops | F14: systems/empirical | G14: 24 | H14: 10.3390/electronics14091775 | I14: =VLOOKUP($D14,Scopus!$A$2:$K$49,3,FALSE) -> 83.0% 35/203 Signal Processing | J14: =VLOOKUP($D14,Scopus!$A$2:$K$49,10,FALSE) -> Q2 | K14: =VLOOKUP($D14,Scopus!$A$2:$K$49,11,FALSE) -> 2079-9292 | L14: =VLOOKUP(H14,$M$1:$Z$40,14,FALSE) -> #N/A | M14: P13 | N14: Retail Resilience Engine: An Agentic AI Framework for Building Reliable Retail Systems | O14: IEEE Access | P14: 10.1109/ACCESS.2025.3552592 | Q14: A1 | R14: 0.9 | S14: Q1 | T14: 2169-3536 | U14: 2025 | V14: 29 | W14: 33 | X14: 31 | Y14: 46230 | Z14: P13
... A40: Variational LSTM Enhanced Anomaly Detection for Industrial Big Data | B40: Xiaokang Zhou; Yiyong Hu; Wei Liang; Jianhua Ma; Qun Jin | C40: 2020 | D40: IEEE Transactions on Industrial Informatics | E40: Automated remediation | F40: unscreened(rule-classified) | G40: 401 | H40: 10.1109/tii.2020.3022432 | I40: =VLOOKUP($D40,Scopus!$A$2:$K$49,3,FALSE) -> 98.0% 10/519 Information Systems | J40: =VLOOKUP($D40,Scopus!$A$2:$K$49,10,FALSE) -> Q1 | K40: =VLOOKUP($D40,Scopus!$A$2:$K$49,11,FALSE) -> 1551-3203 | L40: =VLOOKUP(H40,$M$1:$Z$40,14,FALSE) -> #N/A | M40: P40 | N40: A Comprehensive Survey on LLM-Based Network Management and Operations | O40: International Journal of Network Management | P40: 10.1002/nem.70029 | Q40: A3 | R40: 0.68 | S40: Q2 | T40: 1055-7148 | U40: 2025 | V40: 11 | W40: 13 | X40: 7 | Y40: 46230 | Z40: P40
A41: Artificial Intelligence for Predictive Maintenance Applications: Key Components, Trustworthiness, and Future Trends | B41: Ayşegül Uçar; Mehmet Karaköse; Necim Kırımça | C41: 2024 | D41: Applied Sciences | E41: Detection (classical ML) | F41: survey/position | G41: 396 | H41: 10.3390/app14020898 | I41: =VLOOKUP($D41,Scopus!$A$2:$K$49,3,FALSE) -> 82.0% 18/99 Fluid Flow and Transfer Processes | J41: =VLOOKUP($D41,Scopus!$A$2:$K$49,10,FALSE) -> Q2 | K41: =VLOOKUP($D41,Scopus!$A$2:$K$49,11,FALSE) -> 2076-3417 | L41: =VLOOKUP(H41,$M$1:$Z$40,14,FALSE) -> #N/A
A42: Deep Industrial Image Anomaly Detection: A Survey | B42: Jiaqi Liu; Guoyang Xie; Jinbao Wang; Shangnian Li; Chengjie Wang; Feng Zheng; Yaochu Jin | C42: 2024 | D42: Machine Intelligence Research | E42: Detection (classical ML) | F42: survey/position | G42: 389 | H42: 10.1007/s11633-023-1459-z | I42: =VLOOKUP($D42,Scopus!$A$2:$K$49,3,FALSE) -> 99.0% 2/397 Modeling and Simulation | J42: =VLOOKUP($D42,Scopus!$A$2:$K$49,10,FALSE) -> Q1 | K42: =VLOOKUP($D42,Scopus!$A$2:$K$49,11,FALSE) -> 2731-538X | L42: =VLOOKUP(H42,$M$1:$Z$40,14,FALSE) -> #N/A
A43: Anomaly detection with density estimation | B43: Benjamin Nachman; David Shih | C43: 2020 | D43: Physical review D | E43: Detection (classical ML) | F43: systems/empirical | G43: 315 | H43: 10.1103/physrevd.101.075042 | I43: =VLOOKUP($D43,Scopus!$A$2:$K$49,3,FALSE) -> 93.0% 7/97 Nuclear and High Energy Physics | J43: =VLOOKUP($D43,Scopus!$A$2:$K$49,10,FALSE) -> Q1 | K43: =VLOOKUP($D43,Scopus!$A$2:$K$49,11,FALSE) -> 2470-0010 | L43: =VLOOKUP(H43,$M$1:$Z$40,14,FALSE) -> #N/A
A44: From Corrective to Predictive Maintenance—A Review of Maintenance Approaches for the Power Industry | B44: Marek Molęda; Bożena Małysiak-Mrozek; Weiping Ding; Vaidy Sunderam; Dariusz Mrozek | C44: 2023 | D44: Sensors | E44: Detection (classical ML) | F44: survey/position | G44: 264 | H44: 10.3390/s23135970 | I44: =VLOOKUP($D44,Scopus!$A$2:$K$49,3,FALSE) -> 91.0% 19/206 Instrumentation | J44: =VLOOKUP($D44,Scopus!$A$2:$K$49,10,FALSE) -> Q1 | K44: =VLOOKUP($D44,Scopus!$A$2:$K$49,11,FALSE) -> 1424-8220 | L44: =VLOOKUP(H44,$M$1:$Z$40,14,FALSE) -> #N/A
A45: From knowledge-based to big data analytic model: a novel IoT and machine learning based decision support system for predictive maintenance in Industry 4.0 | B45: Riccardo Rosati; Luca Romeo; Gianalberto Cecchini; F. Tonetto; Paolo Viti; Adriano Mancini; Emanuele Frontoni | C45: 2022 | D45: Journal of Intelligent Manufacturing | E45: Detection (classical ML) | F45: systems/empirical | G45: 247 | H45: 10.1007/s10845-022-01960-x | I45: =VLOOKUP($D45,Scopus!$A$2:$K$49,3,FALSE) -> 96.0% 17/503 Software | J45: =VLOOKUP($D45,Scopus!$A$2:$K$49,10,FALSE) -> Q1 | K45: =VLOOKUP($D45,Scopus!$A$2:$K$49,11,FALSE) -> 0956-5515 | L45: =VLOOKUP(H45,$M$1:$Z$40,14,FALSE) -> #N/A
A46: A Neuroergonomics Approach to Mental Workload, Engagement and Human Performance | B46: Frédéric Dehais; Alex Lafont; Raphaëlle N. Roy; Stephen Fairclough | C46: 2020 | D46: Frontiers in Neuroscience | E46: Human factors | F46: survey/position | G46: 245 | H46: 10.3389/fnins.2020.00268 | I46: =VLOOKUP($D46,Scopus!$A$2:$K$49,3,FALSE) -> 74.0% 29/112 General Neuroscience | J46: =VLOOKUP($D46,Scopus!$A$2:$K$49,10,FALSE) -> Q2 | K46: =VLOOKUP($D46,Scopus!$A$2:$K$49,11,FALSE) -> 1662-453X | L46: =VLOOKUP(H46,$M$1:$Z$40,14,FALSE) -> #N/A
A47: The Chatbot Usability Scale: the Design and Pilot of a Usability Scale for Interaction with AI-Based Conversational Agents | B47: Simone Borsci; Alessio Malizia; Martin Schmettow; Frank van der Velde; Gunay Tariverdiyeva; Divyaa Balaji; Alan Chamberlain | C47: 2021 | D47: Personal and Ubiquitous Computing | E47: Benchmarks & evaluation | F47: unscreened(rule-classified) | G47: 233 | H47: 10.1007/s00779-021-01582-9 | I47: =VLOOKUP($D47,Scopus!$A$2:$K$49,3,FALSE) -> 92.0% 24/296 Library and Information Sciences | J47: =VLOOKUP($D47,Scopus!$A$2:$K$49,10,FALSE) -> Q2 | K47: =VLOOKUP($D47,Scopus!$A$2:$K$49,11,FALSE) -> 1617-4909 | L47: =VLOOKUP(H47,$M$1:$Z$40,14,FALSE) -> #N/A
A48: A Review of Machine Learning and Deep Learning Techniques for Anomaly Detection in IoT Data | B48: Redhwan Al-amri; Raja Kumar Murugesan; Mustafa Man; Alaa Fareed; Mohammed A. Al‐Sharafi; Ammar Ahmed Alkahtani | C48: 2021 | D48: Applied Sciences | E48: Detection (classical ML) | F48: survey/position | G48: 202 | H48: 10.3390/app11125320 | I48: =VLOOKUP($D48,Scopus!$A$2:$K$49,3,FALSE) -> 82.0% 18/99 Fluid Flow and Transfer Processes | J48: =VLOOKUP($D48,Scopus!$A$2:$K$49,10,FALSE) -> Q2 | K48: =VLOOKUP($D48,Scopus!$A$2:$K$49,11,FALSE) -> 2076-3417 | L48: =VLOOKUP(H48,$M$1:$Z$40,14,FALSE) -> #N/A
A49: Deep learning for anomaly detection in log data: A survey | B49: Max Landauer; Sebastian Onder; Florian Skopik; Markus Wurzenberger | C49: 2023 | D49: Machine Learning with Applications | E49: Detection (classical ML) | F49: survey/position | G49: 194 | H49: 10.1016/j.mlwa.2023.100470 | I49: =VLOOKUP($D49,Scopus!$A$2:$K$49,3,FALSE) -> 93.0% 13/203 Computational Theory and Mathematics | J49: =VLOOKUP($D49,Scopus!$A$2:$K$49,10,FALSE) -> Q1 | K49: =VLOOKUP($D49,Scopus!$A$2:$K$49,11,FALSE) -> 2666-8270 | L49: =VLOOKUP(H49,$M$1:$Z$40,14,FALSE) -> #N/A
A50: Zero Touch Management: A Survey of Network Automation Solutions for 5G and 6G Networks | B50: Estefanía Coronado; Rasoul Behravesh; Tejas Subramanya; Adriana Fernández–Fernández; Muhammad Shuaib Siddiqui; Xavier Costa‐Pérez; Roberto Riggio | C50: 2022 | D50: IEEE Communications Surveys and Tutorials | E50: Security IR / SOC | F50: unscreened(rule-classified) | G50: 176 | H50: 10.1109/comst.2022.3212586 | I50: =VLOOKUP($D50,Scopus!$A$2:$K$49,3,FALSE) -> 99.0% 1/1030 Electrical and Electronic Engineering | J50: =VLOOKUP($D50,Scopus!$A$2:$K$49,10,FALSE) -> Q1 | K50: =VLOOKUP($D50,Scopus!$A$2:$K$49,11,FALSE) -> 1553-877X | L50: =VLOOKUP(H50,$M$1:$Z$40,14,FALSE) -> #N/A
A51: EADN: An Efficient Deep Learning Model for Anomaly Detection in Videos | B51: Sareer Ul Amin; Mohib Ullah; Muhammad Sajjad; Faouzi Alaya Cheikh; Mohammad Hijji; Abdulrahman Hijji; Khan Muhammad | C51: 2022 | D51: Mathematics | E51: Detection (classical ML) | F51: systems/empirical | G51: 142 | H51: 10.3390/math10091555 | I51: =VLOOKUP($D51,Scopus!$A$2:$K$49,3,FALSE) -> 92.0% 33/414 General Mathematics | J51: =VLOOKUP($D51,Scopus!$A$2:$K$49,10,FALSE) -> Q2 | K51: =VLOOKUP($D51,Scopus!$A$2:$K$49,11,FALSE) -> 2227-7390 | L51: =VLOOKUP(H51,$M$1:$Z$40,14,FALSE) -> #N/A
A52: Towards Synoptic Water Monitoring Systems: A Review of AI Methods for Automating Water Body Detection and Water Quality Monitoring Using Remote Sensing | B52: Liping Yang; Joshua Driscol; Sarigai Sarigai; Qiusheng Wu; Christopher D. Lippitt; Melinda Morgan | C52: 2022 | D52: Sensors | E52: Detection (classical ML) | F52: unscreened(rule-classified) | G52: 124 | H52: 10.3390/s22062416 | I52: =VLOOKUP($D52,Scopus!$A$2:$K$49,3,FALSE) -> 91.0% 19/206 Instrumentation | J52: =VLOOKUP($D52,Scopus!$A$2:$K$49,10,FALSE) -> Q1 | K52: =VLOOKUP($D52,Scopus!$A$2:$K$49,11,FALSE) -> 1424-8220 | L52: =VLOOKUP(H52,$M$1:$Z$40,14,FALSE) -> #N/A
... A89: An LLM-Based Agentic Network Traffic Incident-Report Approach Towards Explainable-AI Network Defense | B89: Chia-Hong Chou; Arjun Sudheer; Younghee Park | C89: 2026 | D89: Journal of Sensor and Actuator Networks | E89: LLM / agentic ops | F89: systems/empirical | G89: 1 | H89: 10.3390/jsan15020032 | I89: =VLOOKUP($D89,Scopus!$A$2:$K$49,3,FALSE) -> 97.0% 6/198 Control and Optimization | J89: =VLOOKUP($D89,Scopus!$A$2:$K$49,10,FALSE) -> Q2 | K89: =VLOOKUP($D89,Scopus!$A$2:$K$49,11,FALSE) -> 2224-2708 | L89: =VLOOKUP(H89,$M$1:$Z$40,14,FALSE) -> #N/A
A90: VAGNet: Vision-based Accident Anticipation with Global Features | B90: Vipooshan Vipulananthan; Charith D. Chitraranjan | C90: 2026 | D90: IEEE Open Journal of Vehicular Technology, vol. 7, pp. 1873-1883, 2026 | E90: Alert triage & correlation | F90: unscreened(rule-classified) | H90: 10.1109/ojvt.2026.3704953 | I90: =VLOOKUP($D90,Scopus!$A$2:$K$49,3,FALSE) -> #N/A | J90: =VLOOKUP($D90,Scopus!$A$2:$K$49,10,FALSE) -> #N/A | K90: =VLOOKUP($D90,Scopus!$A$2:$K$49,11,FALSE) -> #N/A | L90: =VLOOKUP(H90,$M$1:$Z$40,14,FALSE) -> #N/A
A91: TELESTO: A Graph Neural Network Model for Anomaly Classification in Cloud Services | B91: Dominik Scheinert; Alexander Acker | C91: 2021 | D91: Springer ICSOC LNCS 12632 (2020) 214-227 | E91: Automated remediation | F91: unscreened(rule-classified) | H91: 10.1007/978-3-030-76352-7_23 | I91: =VLOOKUP($D91,Scopus!$A$2:$K$49,3,FALSE) -> #N/A | J91: =VLOOKUP($D91,Scopus!$A$2:$K$49,10,FALSE) -> #N/A | K91: =VLOOKUP($D91,Scopus!$A$2:$K$49,11,FALSE) -> #N/A | L91: =VLOOKUP(H91,$M$1:$Z$40,14,FALSE) -> #N/A
A92: A Decentralised Self-Healing Approach for Network Topology Maintenance | B92: Arles Rodríguez; Jonatan Gómez; Ada Diaconescu | C92: 2020 | D92: Autonomous Agents and Multi-Agent Systems | E92: Automated remediation | F92: systems/empirical | H92: 10.1007/s10458-020-09486-3 | I92: =VLOOKUP($D92,Scopus!$A$2:$K$49,3,FALSE) -> 76.0% 137/570 Artificial Intelligence | J92: =VLOOKUP($D92,Scopus!$A$2:$K$49,10,FALSE) -> Q2 | K92: =VLOOKUP($D92,Scopus!$A$2:$K$49,11,FALSE) -> 1387-2532 | L92: =VLOOKUP(H92,$M$1:$Z$40,14,FALSE) -> #N/A
A93: A unified framework for detecting point and collective anomalies in operating system logs via collaborative transformers | B93: Mohammad Nasirzadeh; Jafar Tahmoresnezhad; Parviz Rashidi-Khazaee | C93: 2025 | D93: Scientific Reports | E93: Detection (classical ML) | F93: systems/empirical | H93: 10.1038/s41598-025-27693-4 | I93: =VLOOKUP($D93,Scopus!$A$2:$K$49,3,FALSE) -> 87.0% 29/223 | J93: =VLOOKUP($D93,Scopus!$A$2:$K$49,10,FALSE) -> Q1 | K93: =VLOOKUP($D93,Scopus!$A$2:$K$49,11,FALSE) -> 2045-2322 | L93: =VLOOKUP(H93,$M$1:$Z$40,14,FALSE) -> #N/A
A94: TARGET: Automated Scenario Generation from Traffic Rules for Testing Autonomous Vehicles via Validated LLM-Guided Knowledge Extraction | B94: Yao Deng; Jiaohong Yao; Zhi Tu; Xi Zheng; Mengshi Zhang; Tianyi Zhang | C94: 2023 | D94: IEEE Transactions on Software Engineering | E94: LLM / agentic ops | F94: unscreened(rule-classified) | H94: 10.1109/tse.2025.3569086 | I94: =VLOOKUP($D94,Scopus!$A$2:$K$49,3,FALSE) -> 92.0% 36/503 Software | J94: =VLOOKUP($D94,Scopus!$A$2:$K$49,10,FALSE) -> Q1 | K94: =VLOOKUP($D94,Scopus!$A$2:$K$49,11,FALSE) -> 0098-5589 | L94: =VLOOKUP(H94,$M$1:$Z$40,14,FALSE) -> #N/A

Sheet Scopus
A1: https://www.scopus.com/sources.uri | B1: 2026-09-06 12:28 (GMT-3)
A2: Source title | B2: CiteScore | C2: Highest percentile | D2: 2022-25 Citations | E2: 2022-25 Documents | F2: % Cited | G2: SNIP | H2: SJR | I2: Publisher | J2: SJR Quartile | K2: ISSN / e-ISSN | P2: Venue | Q2: cluster | R2: paper_type | S2: citations | T2: doi | U2: Scopus (Percentil) | V2: SJR Quartile | W2: ISSN / e-ISSN | AB2: Venue | AC2: SJR | AD2: ISSN | AE2: SJR Site Details
A3: IEEE Communications Surveys and Tutorials | B3: 98.7 | C3: 99.0% 1/1030 Electrical and Electronic Engineering | D3: 33254 | E3: 337 | F3: 99 | G3: 14.933 | H3: 14.838 | I3: IEEE | J3: Q1 | K3: 1553-877X | P3: Telecommunications Policy | Q3: Security IR / SOC | R3: unscreened(rule-classified) | S3: 51 | T3: 10.1016/j.telpol.2025.102976 | U3: 0.97 | V3: Q1 | W3: 0308-5961 | X3: =VLOOKUP(P3,A2:$K$45,2,FALSE) -> 12.7 | AB3: IEEE Transactions on Software Engineering | AC3: Q1 | AD3: 0098-5589 | AE3: =CONCATENATE("https://www.scimagojr.com/journalsearch.php?q=",AD3) -> https://www.scimagojr.com/journalsearch.php?q=0098-5589
A4: ACM Computing Surveys | B4: 65.2 | C4: 99.0% 1/241 General Computer Science | D4: 90231 | E4: 1383 | F4: 92 | G4: 11.121 | H4: 5.985 | I4: Association for Computing Machinery | J4: Q1 | K4: 0360-0300 | P4: ACM Computing Surveys | Q4: Detection (classical ML) | R4: survey/position | S4: 506 | T4: 10.1145/3691338 | U4: 0.99 | V4: Q1 | W4: 0360-0300 | X4: =VLOOKUP(P4,A3:$K$45,2,FALSE) -> 65.2 | AB4: Scientific Reports | AC4: Q1 | AD4: 2045-2322 | AE4: =CONCATENATE("https://www.scimagojr.com/journalsearch.php?q=",AD4) -> https://www.scimagojr.com/journalsearch.php?q=2045-2322
A5: Artificial Intelligence Review | B5: 36.1 | C5: 99.0% 1/1221 Linguistics and Language | D5: 48984 | E5: 1358 | F5: 94 | G5: 6.191 | H5: 3.638 | I5: Springer Nature | J5: Q1 | K5: 0269-2821 | P5: Expert Systems with Applications | Q5: Agent foundations | R5: unscreened(rule-classified) | S5: 59 | T5: 10.1016/j.eswa.2025.128404 | U5: 0.97 | V5: Q1 | W5: 0957-4174 | X5: =VLOOKUP(P5,A4:$K$45,2,FALSE) -> 17 | AB5: Autonomous Agents and Multi-Agent Systems | AC5: Q2 | AD5: 1387-2532 | AE5: =CONCATENATE("https://www.scimagojr.com/journalsearch.php?q=",AD5) -> https://www.scimagojr.com/journalsearch.php?q=1387-2532
A6: Information Fusion | B6: 26.7 | C6: 99.0% 1/203 Signal Processing | D6: 43665 | E6: 1635 | F6: 93 | G6: 4.517 | H6: 4.197 | I6: Elsevier | J6: Q1 | K6: 1566-2535 | P6: ACM Transactions on Software Engineering and Methodology | Q6: Agent foundations | R6: unscreened(rule-classified) | S6: 177 | T6: 10.1145/3712003 | U6: 0.82 | V6: Q1 | W6: 1049-331X | X6: =VLOOKUP(P6,A5:$K$45,2,FALSE) -> 11.6 | AB6: IEEE Open Journal of Vehicular Technology | AC6: Q1 | AD6: 2644-1330 | AE6: =CONCATENATE("https://www.scimagojr.com/journalsearch.php?q=",AD6) -> https://www.scimagojr.com/journalsearch.php?q=2644-1330
A7: IEEE Transactions on Industrial Informatics | B7: 22.4 | C7: 98.0% 10/519 Information Systems | D7: 90744 | E7: 4055 | F7: 91 | G7: 2.607 | H7: 2.983 | I7: IEEE | J7: Q1 | K7: 1551-3203 | P7: Information Fusion | Q7: Agent foundations | R7: survey/position | S7: 169 | T7: 10.1016/j.inffus.2025.103599 | U7: 0.99 | V7: Q1 | W7: 1566-2535 | X7: =VLOOKUP(P7,A6:$K$45,2,FALSE) -> 26.7 | AB7: Journal of Sensor and Actuator Networks | AC7: Q2 | AD7: 2224-2708 | AE7: =CONCATENATE("https://www.scimagojr.com/journalsearch.php?q=",AD7) -> https://www.scimagojr.com/journalsearch.php?q=2224-2708
A8: IEEE Transactions on Intelligent Transportation Systems | B8: 20.5 | C8: 98.0% 2/143 Automotive Engineering | D8: 129839 | E8: 6346 | F8: 88 | G8: 2.758 | H8: 2.608 | I8: IEEE | J8: Q1 | K8: 1524-9050 | P8: IEEE Transactions on Services Computing | Q8: Detection (classical ML) | R8: unscreened(rule-classified) | S8: 217 | T8: 10.1109/tsc.2020.2993728 | U8: 0.9 | V8: Q1 | W8: 1939-1374 | X8: =VLOOKUP(P8,A7:$K$45,2,FALSE) -> 12.9 | AB8: Journal of Universal Computer Science | AC8: Q3 | AD8: 0948-695X | AE8: =CONCATENATE("https://www.scimagojr.com/journalsearch.php?q=",AD8) -> https://www.scimagojr.com/journalsearch.php?q=0948-695X
A9: Journal of Intelligent Manufacturing | B9: 18.5 | C9: 96.0% 17/503 Software | D9: 14942 | E9: 808 | F9: 96 | G9: 2.771 | H9: 1.888 | I9: Springer Nature | J9: Q1 | K9: 0956-5515 | P9: IEEE Transactions on Services Computing | Q9: LLM / agentic ops | R9: unscreened(rule-classified) | S9: 7 | T9: 10.1109/TSC.2025.3629066 | U9: 0.9 | V9: Q1 | W9: 1939-1374 | X9: =VLOOKUP(P9,A8:$K$45,2,FALSE) -> 12.9 | AB9: Computational Intelligence and Neuroscience | AC9: Sem Classificação | AD9: 1687-5265 | AE9: =CONCATENATE("https://www.scimagojr.com/journalsearch.php?q=",AD9) -> https://www.scimagojr.com/journalsearch.php?q=1687-5265
A10: Machine Intelligence Research | B10: 17.8 | C10: 99.0% 2/397 Modeling and Simulation | D10: 4087 | E10: 229 | F10: 77 | G10: 3.072 | H10: 1.894 | I10: Chinese Academy of Sciences | J10: Q1 | K10: 2731-538X | P10: IEEE Transactions on Services Computing | Q10: Root-cause analysis | R10: unscreened(rule-classified) | S10: 0 | T10: 10.1109/TSC.2025.3631913 | U10: 0.9 | V10: Q1 | W10: 1939-1374 | X10: =VLOOKUP(P10,A9:$K$45,2,FALSE) -> 12.9 | AB10: Cognition, Technology and Work | AC10: Q1 | AD10: 1435-5558 | AE10: =CONCATENATE("https://www.scimagojr.com/journalsearch.php?q=",AD10) -> https://www.scimagojr.com/journalsearch.php?q=1435-5558
A11: Expert Systems with Applications | B11: 17 | C11: 97.0% 10/351 General Engineering | D11: 190824 | E11: 11200 | F11: 91 | G11: 2.421 | H11: 1.939 | I11: Elsevier | J11: Q1 | K11: 0957-4174 | P11: Algorithms | Q11: Security IR / SOC | R11: unscreened(rule-classified) | S11: 44 | T11: 10.3390/a18080499 | U11: 0.78 | V11: Q2 | W11: 1999-4893 | X11: =VLOOKUP(P11,A10:$K$45,2,FALSE) -> 5.4 | AB11: Quality and Reliability Engineering International | AC11: Q2 | AD11: 0748-8017 | AE11: =CONCATENATE("https://www.scimagojr.com/journalsearch.php?q=",AD11) -> https://www.scimagojr.com/journalsearch.php?q=0748-8017
A12: IEEE Transactions on Software Engineering | B12: 13.9 | C12: 92.0% 36/503 Software | D12: 13396 | E12: 966 | F12: 84 | G12: 2.412 | H12: 1.568 | I12: IEEE | J12: Q1 | K12: 0098-5589 | P12: Future Internet | Q12: Security IR / SOC | R12: unscreened(rule-classified) | S12: 126 | T12: 10.3390/fi17090404 | U12: 0.84 | V12: Q1 | W12: 1999-5903 | X12: =VLOOKUP(P12,A11:$K$45,2,FALSE) -> 10 | AB12: Journal of International Crisis and Risk Communication Research | AC12: Sem Classificação | AD12: 2576-0017 | AE12: =CONCATENATE("https://www.scimagojr.com/journalsearch.php?q=",AD12) -> https://www.scimagojr.com/journalsearch.php?q=2576-0017
A13: Computers and Industrial Engineering | B13: 13.5 | C13: 96.0% 12/351 General Engineering | D13: 42857 | E13: 3171 | F13: 88 | G13: 1.788 | H13: 1.588 | I13: Elsevier | J13: Q1 | K13: 0360-8352 | P13: F1000Research | Q13: LLM / agentic ops | R13: unscreened(rule-classified) | S13: 21 | T13: 10.12688/f1000research.169927.1 | U13: 0.77 | V13: Q1 | W13: 2046-1402 | X13: =VLOOKUP(P13,A12:$K$45,2,FALSE) -> 2.9 | AB13: Intelligent Systems with Applications | AC13: Q1 | AD13: 2667-3053 | AE13: =CONCATENATE("https://www.scimagojr.com/journalsearch.php?q=",AD13) -> https://www.scimagojr.com/journalsearch.php?q=2667-3053
A14: Intelligent Systems with Applications | B14: 13.1 | C14: 93.0% 12/179 Computer Science (miscellaneous) | D14: 6884 | E14: 526 | F14: 85 | G14: 1.862 | H14: 1.142 | I14: Elsevier | J14: Q1 | K14: 2667-3053 | P14: F1000Research | Q14: Security IR / SOC | R14: survey/position | S14: 13 | T14: 10.12688/f1000research.169337.1 | U14: 0.77 | V14: Q1 | W14: 2046-1402 | X14: =VLOOKUP(P14,A13:$K$45,2,FALSE) -> 2.9 | AB14: Journal of Computational Analysis and Applications | AC14: Sem Classificação | AD14: 1521-1398 | AE14: =CONCATENATE("https://www.scimagojr.com/journalsearch.php?q=",AD14) -> https://www.scimagojr.com/journalsearch.php?q=1521-1398
... A40: Algorithms | B40: 5.4 | C40: 84.0% 34/212 Computational Mathematics | D40: 13039 | E40: 2409 | F40: 72 | G40: 1.01 | H40: 0.57 | I40: Multidisciplinary Digital Publishing Institute (MDPI) | J40: Q2 | K40: 1999-4893 | P40: Array | Q40: LLM / agentic ops | R40: unscreened(rule-classified) | S40: 216 | T40: 10.1016/j.array.2025.100399 | U40: 0.88 | V40: Q1 | W40: 2590-0056 | X40: =VLOOKUP(P40,A39:$K$45,2,FALSE) -> #N/A | AB40: Algorithms | AC40: Q2 | AD40: 1999-4893 | AE40: =CONCATENATE("https://www.scimagojr.com/journalsearch.php?q=",AD40) -> https://www.scimagojr.com/journalsearch.php?q=1999-4893
A41: Mathematics | B41: 5.4 | C41: 92.0% 33/414 General Mathematics | D41: 95684 | E41: 17727 | F41: 73 | G41: 0.932 | H41: 0.497 | I41: Multidisciplinary Digital Publishing Institute (MDPI) | J41: Q2 | K41: 2227-7390 | P41: IEEE Transactions on Industrial Informatics | Q41: Automated remediation | R41: unscreened(rule-classified) | S41: 401 | T41: 10.1109/tii.2020.3022432 | U41: #N/A | V41: Q1 | W41: 1551-3203 | X41: =VLOOKUP(P41,A40:$K$45,2,FALSE) -> #N/A | AB41: IEEE Transactions on Services Computing | AC41: Q1 | AD41: 1939-1374 | AE41: =CONCATENATE("https://www.scimagojr.com/journalsearch.php?q=",AD41) -> https://www.scimagojr.com/journalsearch.php?q=1939-1374
A42: Computational Intelligence | B42: 5.3 | C42: 83.0% 36/212 Computational Mathematics | D42: 1679 | E42: 316 | F42: 68 | G42: 0.775 | H42: 0.488 | I42: John Wiley & Sons | J42: Q2 | K42: 0824-7935 | P42: Applied Sciences | Q42: Detection (classical ML) | R42: survey/position | S42: 396 | T42: 10.3390/app14020898 | U42: #N/A | V42: #N/A | W42: #N/A | X42: =VLOOKUP(P42,A41:$K$45,2,FALSE) -> #N/A | AB42: Information Fusion | AC42: Q1 | AD42: 1566-2535 | AE42: =CONCATENATE("https://www.scimagojr.com/journalsearch.php?q=",AD42) -> https://www.scimagojr.com/journalsearch.php?q=1566-2535
A43: Computation | B43: 5.2 | C43: 85.0% 101/680 Applied Mathematics | D43: 5224 | E43: 1014 | F43: 73 | G43: 0.988 | H43: 0.477 | I43: Multidisciplinary Digital Publishing Institute (MDPI) | J43: Q2 | K43: 2079-3197 | P43: Machine Intelligence Research | Q43: Detection (classical ML) | R43: survey/position | S43: 389 | T43: 10.1007/s11633-023-1459-z | U43: #N/A | V43: #N/A | W43: #N/A | X43: =VLOOKUP(P43,A42:$K$45,2,FALSE) -> #N/A | AB43: ACM Transactions on Software Engineering and Methodology | AC43: Q1 | AD43: 1049-331X | AE43: =CONCATENATE("https://www.scimagojr.com/journalsearch.php?q=",AD43) -> https://www.scimagojr.com/journalsearch.php?q=1049-331X
A44: F1000Research | B44: 2.9 | C44: 79.0% 139/692 Arts and Humanities (miscellaneous) | D44: 7558 | E44: 2612 | F44: 64 | G44: 0.641 | H44: 0.432 | I44: Taylor & Francis | J44: Q1 | K44: 2046-1402 | P44: Physical review. D/Physical review. D. | Q44: Detection (classical ML) | R44: systems/empirical | S44: 315 | T44: 10.1103/physrevd.101.075042 | U44: #N/A | V44: #N/A | W44: #N/A | X44: =VLOOKUP(P44,A43:$K$45,2,FALSE) -> #N/A | AB44: Expert Systems with Applications | AC44: Q1 | AD44: 0957-4174 | AE44: =CONCATENATE("https://www.scimagojr.com/journalsearch.php?q=",AD44) -> https://www.scimagojr.com/journalsearch.php?q=0957-4174
A45: Journal of Universal Computer Science | B45: 2.6 | C45: 47.0% 71/135 Theoretical Computer Science | D45: 681 | E45: 258 | F45: 62 | G45: 0.491 | H45: 0.308 | I45: Technische Universitat Graz from Austria | J45: Q3 | K45: 0948-695X | P45: Sensors | Q45: Detection (classical ML) | R45: survey/position | S45: 264 | T45: 10.3390/s23135970 | U45: #N/A | V45: #N/A | W45: #N/A | X45: =VLOOKUP(P45,A44:$K$45,2,FALSE) -> #N/A | AB45: ACM Computing Surveys | AC45: Q1 | AD45: 0360-0300 | AE45: =CONCATENATE("https://www.scimagojr.com/journalsearch.php?q=",AD45) -> https://www.scimagojr.com/journalsearch.php?q=0360-0300
A46: IEEE Access | B46: 9.3 | C46: 91.0% 31/351 General Engineering | D46: 437277 | E46: 46875 | F46: 79 | G46: 1.483 | H46: 0.884 | I46: IEEE | J46: Q1 | K46: 2169-3536 | P46: Journal of Intelligent Manufacturing | Q46: Detection (classical ML) | R46: systems/empirical | S46: 247 | T46: 10.1007/s10845-022-01960-x | U46: #N/A | V46: #N/A | W46: #N/A | X46: =VLOOKUP(P46,A45:$K$45,2,FALSE) -> #N/A | AB46: Telecommunications Policy | AC46: Q1 | AD46: 0308-5961 | AE46: =CONCATENATE("https://www.scimagojr.com/journalsearch.php?q=",AD46) -> https://www.scimagojr.com/journalsearch.php?q=0308-5961
A47: Electronics | B47: 7 | C47: 83.0% 35/203 Signal Processing | D47: 134403 | E47: 19097 | F47: 78 | G47: 1.034 | H47: 0.623 | I47: Multidisciplinary Digital Publishing Institute (MDPI) | J47: Q2 | K47: 2079-9292 | P47: Frontiers in Neuroscience | Q47: Human factors | R47: survey/position | S47: 245 | T47: 10.3389/fnins.2020.00268 | U47: #N/A | V47: #N/A | W47: #N/A | X47: =VLOOKUP(P47,A$45:$K46,2,FALSE) -> #N/A | AB47: Array | AC47: Q1 | AD47: 2590-0056 | AE47: =CONCATENATE("https://www.scimagojr.com/journalsearch.php?q=",AD47) -> https://www.scimagojr.com/journalsearch.php?q=2590-0056
A48: Computers | B48: 9.1 | C48: 86.0% 25/179 Computer Science (miscellaneous) | D48: 12296 | E48: 1347 | F48: 74 | G48: 1.8 | H48: 0.935 | I48: Multidisciplinary Digital Publishing Institute (MDPI) | J48: Q1 | K48: 2073-431X | P48: Personal and Ubiquitous Computing | Q48: Benchmarks & evaluation | R48: unscreened(rule-classified) | S48: 233 | T48: 10.1007/s00779-021-01582-9 | U48: #N/A | V48: #N/A | W48: #N/A | X48: =VLOOKUP(P48,A$45:$K47,2,FALSE) -> #N/A | AB48: IEEE Transactions on Industrial Informatics | AC48: Q1 | AD48: 1551-3203 | AE48: =CONCATENATE("https://www.scimagojr.com/journalsearch.php?q=",AD48) -> https://www.scimagojr.com/journalsearch.php?q=1551-3203
A49: Cognition, Technology and Work | B49: 8.2 | C49: 99.0% 9/891 Philosophy | D49: 1228 | E49: 149 | F49: 76 | G49: 1.572 | H49: 0.839 | I49: Springer Nature | J49: Q1 | K49: 1435-5558 | P49: Applied Sciences | Q49: Detection (classical ML) | R49: survey/position | S49: 202 | T49: 10.3390/app11125320 | U49: #N/A | V49: #N/A | W49: #N/A | X49: =VLOOKUP(P49,A$45:$K48,2,FALSE) -> #N/A | AB49: IEEE Access | AC49: Q1 | AD49: 2169-3536 | AE49: =CONCATENATE("https://www.scimagojr.com/journalsearch.php?q=",AD49) -> https://www.scimagojr.com/journalsearch.php?q=2169-3536
A50: Computers and Industrial Engineering | B50: 13.5 | C50: 96.0% 12/351 General Engineering | D50: 42857 | E50: 3171 | F50: 88 | G50: 1.788 | H50: 1.588 | I50: Elsevier | J50: Q1 | K50: 0360-8352 | P50: Machine Learning with Applications | Q50: Detection (classical ML) | R50: survey/position | S50: 194 | T50: 10.1016/j.mlwa.2023.100470 | U50: #N/A | V50: #N/A | W50: #N/A | X50: =VLOOKUP(P50,A$45:$K49,2,FALSE) -> #N/A | AB50: Electronics | AC50: Q2 | AD50: 2079-9292 | AE50: =CONCATENATE("https://www.scimagojr.com/journalsearch.php?q=",AD50) -> https://www.scimagojr.com/journalsearch.php?q=2079-9292
